Workbook
Name Slicer_Delivery_Status: #N/A
Name Slicer_Payment_Method: #N/A
Name Slicer_Region: #N/A

Sheet AmazonSales
A1: Order ID | B1: Order Date | C1: Delivery Date | D1: Average Delivery Time | E1: Cancel Date | F1: Customer ID | G1: Product ID | H1: Category | I1: Region | J1: Sale Price/Unit | K1: Quantity | L1: Total Amount | M1: Payment Method | N1: Delivery Status | O1: Fulfillment Partner | AN1: Order Date | AO1: Delivery Date
A2: ORD0001 | B2: 45291 | E2: 45293 | F2: CUST021 | G2: PROD012 | H2: =VLOOKUP(G2,ProductMaster!A:C,3,0) -> Home | I2: North | J2: 44 | K2: 1 | L2: 44 | M2: Apple Pay | N2: Cancelled | O2: DHL | AN2: 45291
A3: ORD0002 | B3: 44979 | C3: 44981 | D3: 2 | F3: CUST029 | G3: PROD018 | H3: =VLOOKUP(G3,ProductMaster!A:C,3,0) -> Toys | I3: East | J3: 96 | K3: 4 | L3: 384 | M3: Credit Card | N3: Delivered | O3: DHL | AN3: 44979 | AO3: 44981 | AR3: =AO3-AN3 -> 2
A4: ORD0003 | B4: 45210 | F4: CUST021 | G4: PROD013 | H4: =VLOOKUP(G4,ProductMaster!A:C,3,0) -> Home | I4: South | J4: 194 | K4: 4 | L4: 776 | M4: Credit Card | N4: In Transit | O4: USPS | AN4: 45210
A5: ORD0004 | B5: 45051 | E5: 45057 | F5: CUST044 | G5: PROD013 | H5: =VLOOKUP(G5,ProductMaster!A:C,3,0) -> Home | I5: North | J5: 196 | K5: 3 | L5: 588 | M5: PayPal | N5: Cancelled | O5: UPS | AN5: 45051
A6: ORD0005 | B6: 44959 | C6: 44962 | D6: 3 | F6: CUST027 | G6: PROD010 | H6: =VLOOKUP(G6,ProductMaster!A:C,3,0) -> Fashion | I6: North | J6: 59 | K6: 1 | L6: 59 | M6: PayPal | N6: Delivered | O6: Amazon Logistics | AN6: 44959 | AO6: 44962 | AR6: =AO6-AN6 -> 3
A7: ORD0006 | B7: 45231 | E7: 45232 | F7: CUST009 | G7: PROD010 | H7: =VLOOKUP(G7,ProductMaster!A:C,3,0) -> Fashion | I7: North | J7: 58 | K7: 4 | L7: 232 | M7: Amazon Pay | N7: Cancelled | O7: DHL | AN7: 45231
A8: ORD0007 | B8: 45152 | E8: 45156 | F8: CUST042 | G8: PROD020 | H8: =VLOOKUP(G8,ProductMaster!A:C,3,0) -> Electronics | I8: Central | J8: 105 | K8: 3 | L8: 315 | M8: Debit Card | N8: Cancelled | O8: DHL | AN8: 45152
A9: ORD0008 | B9: 45017 | E9: 45022 | F9: CUST019 | G9: PROD021 | H9: =VLOOKUP(G9,ProductMaster!A:C,3,0) -> Home | I9: West | J9: 37 | K9: 5 | L9: 185 | M9: PayPal | N9: Cancelled | O9: DHL | AN9: 45017
A10: ORD0009 | B10: 45128 | F10: CUST013 | G10: PROD019 | H10: =VLOOKUP(G10,ProductMaster!A:C,3,0) -> Fashion | I10: Central | J10: 44 | K10: 2 | L10: 88 | M10: Credit Card | N10: In Transit | O10: Amazon Logistics | AN10: 45128
A11: ORD0010 | B11: 45289 | F11: CUST019 | G11: PROD003 | H11: =VLOOKUP(G11,ProductMaster!A:C,3,0) -> Home | I11: South | J11: 141 | K11: 4 | L11: 564 | M11: Debit Card | N11: In Transit | O11: DHL | AN11: 45289
A12: ORD0011 | B12: 45050 | E12: 45054 | F12: CUST046 | G12: PROD014 | H12: =VLOOKUP(G12,ProductMaster!A:C,3,0) -> Electronics | I12: South | J12: 249 | K12: 1 | L12: 249 | M12: Amazon Pay | N12: Cancelled | O12: USPS | AN12: 45050
A13: ORD0012 | B13: 45132 | F13: CUST045 | G13: PROD014 | H13: =VLOOKUP(G13,ProductMaster!A:C,3,0) -> Electronics | I13: Central | J13: 247 | K13: 3 | L13: 741 | M13: Amazon Pay | N13: In Transit | O13: FedEx | AN13: 45132
A14: ORD0013 | B14: 44982 | E14: 44985 | F14: CUST023 | G14: PROD006 | H14: =VLOOKUP(G14,ProductMaster!A:C,3,0) -> Fashion | I14: Central | J14: 96 | K14: 1 | L14: 96 | M14: Apple Pay | N14: Cancelled | O14: Amazon Logistics | AN14: 44982
A15: ORD0014 | B15: 44981 | E15: 44982 | F15: CUST033 | G15: PROD017 | H15: =VLOOKUP(G15,ProductMaster!A:C,3,0) -> Electronics | I15: West | J15: 74 | K15: 5 | L15: 370 | M15: Apple Pay | N15: Cancelled | O15: Amazon Logistics | AN15: 44981
A16: ORD0015 | B16: 45164 | E16: 45171 | F16: CUST033 | G16: PROD005 | H16: =VLOOKUP(G16,ProductMaster!A:C,3,0) -> Fashion | I16: South | J16: 27 | K16: 1 | L16: 27 | M16: Credit Card | N16: Cancelled | O16: Amazon Logistics | AN16: 45164
A17: ORD0016 | B17: 44970 | F17: CUST047 | G17: PROD005 | H17: =VLOOKUP(G17,ProductMaster!A:C,3,0) -> Fashion | I17: South | J17: 27 | K17: 3 | L17: 81 | M17: Debit Card | N17: In Transit | O17: Amazon Logistics | AN17: 44970
A18: ORD0017 | B18: 45105 | C18: 45108 | D18: 3 | F18: CUST045 | G18: PROD015 | H18: =VLOOKUP(G18,ProductMaster!A:C,3,0) -> Books | I18: East | J18: 21 | K18: 3 | L18: 63 | M18: Credit Card | N18: Delivered | O18: DHL | AN18: 45105 | AO18: 45108 | AR18: =AO18-AN18 -> 3
A19: ORD0018 | B19: 45258 | F19: CUST011 | G19: PROD008 | H19: =VLOOKUP(G19,ProductMaster!A:C,3,0) -> Books | I19: West | J19: 70 | K19: 5 | L19: 350 | M19: PayPal | N19: In Transit | O19: Amazon Logistics | AN19: 45258
A20: ORD0019 | B20: 45163 | F20: CUST041 | G20: PROD006 | H20: =VLOOKUP(G20,ProductMaster!A:C,3,0) -> Fashion | I20: South | J20: 94 | K20: 4 | L20: 376 | M20: Credit Card | N20: In Transit | O20: USPS | AN20: 45163
A21: ORD0020 | B21: 45028 | F21: CUST025 | G21: PROD001 | H21: =VLOOKUP(G21,ProductMaster!A:C,3,0) -> Electronics | I21: North | J21: 813 | K21: 2 | L21: 1626 | M21: Credit Card | N21: In Transit | O21: FedEx | AN21: 45028
A22: ORD0021 | B22: 45201 | F22: CUST013 | G22: PROD015 | H22: =VLOOKUP(G22,ProductMaster!A:C,3,0) -> Books | I22: Central | J22: 21 | K22: 4 | L22: 84 | M22: PayPal | N22: In Transit | O22: Amazon Logistics | AN22: 45201
A23: ORD0022 | B23: 45239 | F23: CUST023 | G23: PROD012 | H23: =VLOOKUP(G23,ProductMaster!A:C,3,0) -> Home | I23: West | J23: 46 | K23: 5 | L23: 230 | M23: PayPal | N23: In Transit | O23: USPS | AN23: 45239
A24: ORD0023 | B24: 44970 | E24: 44971 | F24: CUST016 | G24: PROD010 | H24: =VLOOKUP(G24,ProductMaster!A:C,3,0) -> Fashion | I24: West | J24: 58 | K24: 3 | L24: 174 | M24: Amazon Pay | N24: Cancelled | O24: Amazon Logistics | AN24: 44970
A25: ORD0024 | B25: 45232 | C25: 45235 | D25: 3 | F25: CUST028 | G25: PROD006 | H25: =VLOOKUP(G25,ProductMaster!A:C,3,0) -> Fashion | I25: West | J25: 96 | K25: 5 | L25: 480 | M25: Amazon Pay | N25: Delivered | O25: Amazon Logistics | AN25: 45232 | AO25: 45235 | AR25: =AO25-AN25 -> 3
A26: ORD0025 | B26: 45074 | C26: 45076 | D26: 2 | F26: CUST040 | G26: PROD002 | H26: =VLOOKUP(G26,ProductMaster!A:C,3,0) -> Toys | I26: South | J26: 43 | K26: 1 | L26: 43 | M26: Debit Card | N26: Delivered | O26: Amazon Logistics | AN26: 45074 | AO26: 45076 | AR26: =AO26-AN26 -> 2
A27: ORD0026 | B27: 45214 | C27: 45220 | D27: 6 | F27: CUST027 | G27: PROD022 | H27: =VLOOKUP(G27,ProductMaster!A:C,3,0) -> Fashion | I27: South | J27: 64 | K27: 4 | L27: 256 | M27: Debit Card | N27: Delivered | O27: USPS | AN27: 45214 | AO27: 45220 | AR27: =AO27-AN27 -> 6
A28: ORD0027 | B28: 44942 | F28: CUST018 | G28: PROD008 | H28: =VLOOKUP(G28,ProductMaster!A:C,3,0) -> Books | I28: South | J28: 70 | K28: 2 | L28: 140 | M28: Amazon Pay | N28: In Transit | O28: Amazon Logistics | AN28: 44942
A29: ORD0028 | B29: 45208 | F29: CUST018 | G29: PROD018 | H29: =VLOOKUP(G29,ProductMaster!A:C,3,0) -> Toys | I29: Central | J29: 97 | K29: 3 | L29: 291 | M29: Credit Card | N29: In Transit | O29: Amazon Logistics | AN29: 45208
A30: ORD0029 | B30: 45206 | E30: 45209 | F30: CUST007 | G30: PROD021 | H30: =VLOOKUP(G30,ProductMaster!A:C,3,0) -> Home | I30: East | J30: 37 | K30: 3 | L30: 111 | M30: Apple Pay | N30: Cancelled | O30: DHL | AN30: 45206
A31: ORD0030 | B31: 44971 | F31: CUST008 | G31: PROD008 | H31: =VLOOKUP(G31,ProductMaster!A:C,3,0) -> Books | I31: North | J31: 69 | K31: 5 | L31: 345 | M31: Amazon Pay | N31: In Transit | O31: Amazon Logistics | AN31: 44971
A32: ORD0031 | B32: 45011 | F32: CUST014 | G32: PROD002 | H32: =VLOOKUP(G32,ProductMaster!A:C,3,0) -> Toys | I32: North | J32: 42 | K32: 5 | L32: 210 | M32: Amazon Pay | N32: In Transit | O32: UPS | AN32: 45011
A33: ORD0032 | B33: 45092 | E33: 45099 | F33: CUST037 | G33: PROD009 | H33: =VLOOKUP(G33,ProductMaster!A:C,3,0) -> Books | I33: East | J33: 11 | K33: 5 | L33: 55 | M33: Debit Card | N33: Cancelled | O33: FedEx | AN33: 45092
A34: ORD0033 | B34: 45068 | C34: 45069 | D34: 1 | F34: CUST016 | G34: PROD005 | H34: =VLOOKUP(G34,ProductMaster!A:C,3,0) -> Fashion | I34: South | J34: 27 | K34: 2 | L34: 54 | M34: Apple Pay | N34: Delivered | O34: USPS | AN34: 45068 | AO34: 45069 | AR34: =AO34-AN34 -> 1
A35: ORD0034 | B35: 45250 | F35: CUST025 | G35: PROD015 | H35: =VLOOKUP(G35,ProductMaster!A:C,3,0) -> Books | I35: South | J35: 21 | K35: 1 | L35: 21 | M35: Amazon Pay | N35: In Transit | O35: DHL | AN35: 45250
A36: ORD0035 | B36: 45282 | C36: 45286 | D36: 4 | F36: CUST032 | G36: PROD011 | H36: =VLOOKUP(G36,ProductMaster!A:C,3,0) -> Electronics | I36: South | J36: 172 | K36: 1 | L36: 172 | M36: PayPal | N36: Delivered | O36: USPS | AN36: 45282 | AO36: 45286 | AR36: =AO36-AN36 -> 4
A37: ORD0036 | B37: 45130 | F37: CUST014 | G37: PROD016 | H37: =VLOOKUP(G37,ProductMaster!A:C,3,0) -> Home | I37: North | J37: 212 | K37: 3 | L37: 636 | M37: Amazon Pay | N37: In Transit | O37: UPS | AN37: 45130
A38: ORD0037 | B38: 45216 | C38: 45221 | D38: 5 | F38: CUST044 | G38: PROD002 | H38: =VLOOKUP(G38,ProductMaster!A:C,3,0) -> Toys | I38: East | J38: 41 | K38: 4 | L38: 164 | M38: Credit Card | N38: Delivered | O38: Amazon Logistics | AN38: 45216 | AO38: 45221 | AR38: =AO38-AN38 -> 5
A39: ORD0038 | B39: 45160 | E39: 45162 | F39: CUST028 | G39: PROD007 | H39: =VLOOKUP(G39,ProductMaster!A:C,3,0) -> Toys | I39: North | J39: 32 | K39: 2 | L39: 64 | M39: Debit Card | N39: Cancelled | O39: FedEx | AN39: 45160
A40: ORD0039 | B40: 45262 | F40: CUST024 | G40: PROD022 | H40: =VLOOKUP(G40,ProductMaster!A:C,3,0) -> Fashion | I40: East | J40: 66 | K40: 2 | L40: 132 | M40: Apple Pay | N40: In Transit | O40: DHL | AN40: 45262
...

Sheet Customer Master
A1: Customer ID | B1: Customer Name
A2: CUST001 | B2: James Miller
A3: CUST002 | B3: Emily Johnson
A4: CUST003 | B4: Ethan Davis
A5: CUST004 | B5: Noah Wilson
A6: CUST005 | B6: Olivia Martinez
A7: CUST006 | B7: Ava Robinson
A8: CUST007 | B8: Liam Walker
A9: CUST008 | B9: Harper Young
A10: CUST009 | B10: Jackson Allen
A11: CUST010 | B11: Charlotte Harris
A12: CUST011 | B12: Mason Hall
... A50: CUST049 | B50: Hazel Gray

Sheet Sales
A1: Customer ID | B1: Customer Name | C1: Dalivery
A2: CUST021 | B2: =IFERROR(VLOOKUP(A2,'Customer Master'!A:B,2,0),"Unknown Customer") -> Zoe Mitchell | C2: =IFERROR( IF(AmazonSales!E:E<>"","Cancelled", IF(AmazonSales!C:C="","No Delivery Date", IF(AmazonSales!C:C<AmazonSales!B:B,"Check Dates", IF(AmazonSales!C:C-AmazonSales!B:B<=2,"Fast","Slow") ) ) ), ) -> Cancelled
A3: CUST029 | B3: =IFERROR(VLOOKUP(A3,'Customer Master'!A:B,2,0),"Unknown Customer") -> Ava White | C3: =IFERROR( IF(AmazonSales!E:E<>"","Cancelled", IF(AmazonSales!C:C="","No Delivery Date", IF(AmazonSales!C:C<AmazonSales!B:B,"Check Dates", IF(AmazonSales!C:C-AmazonSales!B:B<=2,"Fast","Slow") ) ) ), ) -> Fast
A4: CUST021 | B4: =IFERROR(VLOOKUP(A4,'Customer Master'!A:B,2,0),"Unknown Customer") -> Zoe Mitchell | C4: =IFERROR( IF(AmazonSales!E:E<>"","Cancelled", IF(AmazonSales!C:C="","No Delivery Date", IF(AmazonSales!C:C<AmazonSales!B:B,"Check Dates", IF(AmazonSales!C:C-AmazonSales!B:B<=2,"Fast","Slow") ) ) ), ) -> No Delivery Date
A5: CUST044 | B5: =IFERROR(VLOOKUP(A5,'Customer Master'!A:B,2,0),"Unknown Customer") -> Grace Ward | C5: =IFERROR( IF(AmazonSales!E:E<>"","Cancelled", IF(AmazonSales!C:C="","No Delivery Date", IF(AmazonSales!C:C<AmazonSales!B:B,"Check Dates", IF(AmazonSales!C:C-AmazonSales!B:B<=2,"Fast","Slow") ) ) ), ) -> Cancelled
A6: CUST027 | B6: =IFERROR(VLOOKUP(A6,'Customer Master'!A:B,2,0),"Unknown Customer") -> Hazel Brooks | C6: =IFERROR( IF(AmazonSales!E:E<>"","Cancelled", IF(AmazonSales!C:C="","No Delivery Date", IF(AmazonSales!C:C<AmazonSales!B:B,"Check Dates", IF(AmazonSales!C:C-AmazonSales!B:B<=2,"Fast","Slow") ) ) ), ) -> Slow
A7: CUST009 | B7: =IFERROR(VLOOKUP(A7,'Customer Master'!A:B,2,0),"Unknown Customer") -> Jackson Allen | C7: =IFERROR( IF(AmazonSales!E:E<>"","Cancelled", IF(AmazonSales!C:C="","No Delivery Date", IF(AmazonSales!C:C<AmazonSales!B:B,"Check Dates", IF(AmazonSales!C:C-AmazonSales!B:B<=2,"Fast","Slow") ) ) ), ) -> Cancelled
A8: CUST042 | B8: =IFERROR(VLOOKUP(A8,'Customer Master'!A:B,2,0),"Unknown Customer") -> Noah Wilson | C8: =IFERROR( IF(AmazonSales!E:E<>"","Cancelled", IF(AmazonSales!C:C="","No Delivery Date", IF(AmazonSales!C:C<AmazonSales!B:B,"Check Dates", IF(AmazonSales!C:C-AmazonSales!B:B<=2,"Fast","Slow") ) ) ), ) -> Cancelled
A9: CUST019 | B9: =IFERROR(VLOOKUP(A9,'Customer Master'!A:B,2,0),"Unknown Customer") -> Ava Robinson | C9: =IFERROR( IF(AmazonSales!E:E<>"","Cancelled", IF(AmazonSales!C:C="","No Delivery Date", IF(AmazonSales!C:C<AmazonSales!B:B,"Check Dates", IF(AmazonSales!C:C-AmazonSales!B:B<=2,"Fast","Slow") ) ) ), ) -> Cancelled
A10: CUST013 | B10: =IFERROR(VLOOKUP(A10,'Customer Master'!A:B,2,0),"Unknown Customer") -> Olivia Martinez | C10: =IFERROR( IF(AmazonSales!E:E<>"","Cancelled", IF(AmazonSales!C:C="","No Delivery Date", IF(AmazonSales!C:C<AmazonSales!B:B,"Check Dates", IF(AmazonSales!C:C-AmazonSales!B:B<=2,"Fast","Slow") ) ) ), ) -> No Delivery Date
A11: CUST019 | B11: =IFERROR(VLOOKUP(A11,'Customer Master'!A:B,2,0),"Unknown Customer") -> Ava Robinson | C11: =IFERROR( IF(AmazonSales!E:E<>"","Cancelled", IF(AmazonSales!C:C="","No Delivery Date", IF(AmazonSales!C:C<AmazonSales!B:B,"Check Dates", IF(AmazonSales!C:C-AmazonSales!B:B<=2,"Fast","Slow") ) ) ), ) -> No Delivery Date
A12: CUST046 | B12: =IFERROR(VLOOKUP(A12,'Customer Master'!A:B,2,0),"Unknown Customer") -> Emily Johnson | C12: =IFERROR( IF(AmazonSales!E:E<>"","Cancelled", IF(AmazonSales!C:C="","No Delivery Date", IF(AmazonSales!C:C<AmazonSales!B:B,"Check Dates", IF(AmazonSales!C:C-AmazonSales!B:B<=2,"Fast","Slow") ) ) ), ) -> Cancelled
A13: CUST045 | B13: =IFERROR(VLOOKUP(A13,'Customer Master'!A:B,2,0),"Unknown Customer") -> Emily Johnson | C13: =IFERROR( IF(AmazonSales!E:E<>"","Cancelled", IF(AmazonSales!C:C="","No Delivery Date", IF(AmazonSales!C:C<AmazonSales!B:B,"Check Dates", IF(AmazonSales!C:C-AmazonSales!B:B<=2,"Fast","Slow") ) ) ), ) -> No Delivery Date
... A101: CUST009 | B101: =IFERROR(VLOOKUP(A101,'Customer Master'!A:B,2,0),"Unknown Customer") -> Jackson Allen | C101: =IFERROR( IF(AmazonSales!E:E<>"","Cancelled", IF(AmazonSales!C:C="","No Delivery Date", IF(AmazonSales!C:C<AmazonSales!B:B,"Check Dates", IF(AmazonSales!C:C-AmazonSales!B:B<=2,"Fast","Slow") ) ) ), ) -> No Delivery Date

Sheet Advance Reporting
B1: Delivery | C1: Delivery Status | D1: Region | E1: Total Amount | F1: Product ID | H1: Count of Delivery Status | I1: Column Labels | M1: Higest selling product | O1: Effective Sales(Delivered) | Q1: % of Fast delivery
B2: =IFERROR( IF(AmazonSales!E:E<>"","Cancelled", IF(AmazonSales!C:C="","No Delivery Date", IF(AmazonSales!C:C<AmazonSales!B:B,"Check Dates", IF(AmazonSales!C:C-AmazonSales!B:B<=2,"Fast","Slow") ) ) ), ) -> Cancelled | C2: Cancelled | D2: South | E2: 27 | F2: PROD005 | H2: Row Labels | I2: Cancelled | J2: Grand Total | M2: =INDEX(F1:F101, MATCH(MAX(E1:E101), E:E, 0)) -> PROD001 | O2: =SUMIF(C:C,C19,E:E) -> 13656 | Q2: =COUNTIF(B:B, "Fast") / COUNTIF(C:C, "Delivered")*100 -> 32.352941
B3: =IFERROR( IF(AmazonSales!E:E<>"","Cancelled", IF(AmazonSales!C:C="","No Delivery Date", IF(AmazonSales!C:C<AmazonSales!B:B,"Check Dates", IF(AmazonSales!C:C-AmazonSales!B:B<=2,"Fast","Slow") ) ) ), ) -> Fast | C3: In Transit | D3: South | E3: 81 | F3: PROD005 | H3: Central | I3: 5 | J3: 5 | M3: =SUMIF(F:F,M2,E:E) -> 9644 | S3: Row Labels | T3: Sum of Total Amount
B4: =IFERROR( IF(AmazonSales!E:E<>"","Cancelled", IF(AmazonSales!C:C="","No Delivery Date", IF(AmazonSales!C:C<AmazonSales!B:B,"Check Dates", IF(AmazonSales!C:C-AmazonSales!B:B<=2,"Fast","Slow") ) ) ), ) -> No Delivery Date | C4: Cancelled | D4: West | E4: 185 | F4: PROD021 | H4: East | I4: 3 | J4: 3 | S4: North | T4: 10491
B5: =IFERROR( IF(AmazonSales!E:E<>"","Cancelled", IF(AmazonSales!C:C="","No Delivery Date", IF(AmazonSales!C:C<AmazonSales!B:B,"Check Dates", IF(AmazonSales!C:C-AmazonSales!B:B<=2,"Fast","Slow") ) ) ), ) -> Cancelled | C5: In Transit | D5: West | E5: 230 | F5: PROD012 | H5: North | I5: 10 | J5: 10 | S5: South | T5: 7317
B6: =IFERROR( IF(AmazonSales!E:E<>"","Cancelled", IF(AmazonSales!C:C="","No Delivery Date", IF(AmazonSales!C:C<AmazonSales!B:B,"Check Dates", IF(AmazonSales!C:C-AmazonSales!B:B<=2,"Fast","Slow") ) ) ), ) -> Slow | C6: In Transit | D6: Central | E6: 741 | F6: PROD014 | H6: South | I6: 4 | J6: 4 | S6: West | T6: 8359
B7: =IFERROR( IF(AmazonSales!E:E<>"","Cancelled", IF(AmazonSales!C:C="","No Delivery Date", IF(AmazonSales!C:C<AmazonSales!B:B,"Check Dates", IF(AmazonSales!C:C-AmazonSales!B:B<=2,"Fast","Slow") ) ) ), ) -> Cancelled | C7: In Transit | D7: South | E7: 564 | F7: PROD003 | H7: West | I7: 8 | J7: 8 | S7: Grand Total | T7: 26167
B8: =IFERROR( IF(AmazonSales!E:E<>"","Cancelled", IF(AmazonSales!C:C="","No Delivery Date", IF(AmazonSales!C:C<AmazonSales!B:B,"Check Dates", IF(AmazonSales!C:C-AmazonSales!B:B<=2,"Fast","Slow") ) ) ), ) -> Cancelled | C8: In Transit | D8: Central | E8: 84 | F8: PROD015 | H8: Grand Total | I8: 30 | J8: 30
B9: =IFERROR( IF(AmazonSales!E:E<>"","Cancelled", IF(AmazonSales!C:C="","No Delivery Date", IF(AmazonSales!C:C<AmazonSales!B:B,"Check Dates", IF(AmazonSales!C:C-AmazonSales!B:B<=2,"Fast","Slow") ) ) ), ) -> Cancelled | C9: Cancelled | D9: West | E9: 370 | F9: PROD017
B10: =IFERROR( IF(AmazonSales!E:E<>"","Cancelled", IF(AmazonSales!C:C="","No Delivery Date", IF(AmazonSales!C:C<AmazonSales!B:B,"Check Dates", IF(AmazonSales!C:C-AmazonSales!B:B<=2,"Fast","Slow") ) ) ), ) -> No Delivery Date | C10: In Transit | D10: West | E10: 350 | F10: PROD008
B11: =IFERROR( IF(AmazonSales!E:E<>"","Cancelled", IF(AmazonSales!C:C="","No Delivery Date", IF(AmazonSales!C:C<AmazonSales!B:B,"Check Dates", IF(AmazonSales!C:C-AmazonSales!B:B<=2,"Fast","Slow") ) ) ), ) -> No Delivery Date | C11: Cancelled | D11: North | E11: 588 | F11: PROD013
B12: =IFERROR( IF(AmazonSales!E:E<>"","Cancelled", IF(AmazonSales!C:C="","No Delivery Date", IF(AmazonSales!C:C<AmazonSales!B:B,"Check Dates", IF(AmazonSales!C:C-AmazonSales!B:B<=2,"Fast","Slow") ) ) ), ) -> Cancelled | C12: In Transit | D12: South | E12: 376 | F12: PROD006
B13: =IFERROR( IF(AmazonSales!E:E<>"","Cancelled", IF(AmazonSales!C:C="","No Delivery Date", IF(AmazonSales!C:C<AmazonSales!B:B,"Check Dates", IF(AmazonSales!C:C-AmazonSales!B:B<=2,"Fast","Slow") ) ) ), ) -> No Delivery Date | C13: Cancelled | D13: North | E13: 44 | F13: PROD012
B14: =IFERROR( IF(AmazonSales!E:E<>"","Cancelled", IF(AmazonSales!C:C="","No Delivery Date", IF(AmazonSales!C:C<AmazonSales!B:B,"Check Dates", IF(AmazonSales!C:C-AmazonSales!B:B<=2,"Fast","Slow") ) ) ), ) -> Cancelled | C14: In Transit | D14: South | E14: 776 | F14: PROD013
B15: =IFERROR( IF(AmazonSales!E:E<>"","Cancelled", IF(AmazonSales!C:C="","No Delivery Date", IF(AmazonSales!C:C<AmazonSales!B:B,"Check Dates", IF(AmazonSales!C:C-AmazonSales!B:B<=2,"Fast","Slow") ) ) ), ) -> Cancelled | C15: In Transit | D15: Central | E15: 88 | F15: PROD019
B16: =IFERROR( IF(AmazonSales!E:E<>"","Cancelled", IF(AmazonSales!C:C="","No Delivery Date", IF(AmazonSales!C:C<AmazonSales!B:B,"Check Dates", IF(AmazonSales!C:C-AmazonSales!B:B<=2,"Fast","Slow") ) ) ), ) -> Cancelled | C16: Cancelled | D16: Central | E16: 96 | F16: PROD006
B17: =IFERROR( IF(AmazonSales!E:E<>"","Cancelled", IF(AmazonSales!C:C="","No Delivery Date", IF(AmazonSales!C:C<AmazonSales!B:B,"Check Dates", IF(AmazonSales!C:C-AmazonSales!B:B<=2,"Fast","Slow") ) ) ), ) -> No Delivery Date | C17: In Transit | D17: North | E17: 1626 | F17: PROD001
B18: =IFERROR( IF(AmazonSales!E:E<>"","Cancelled", IF(AmazonSales!C:C="","No Delivery Date", IF(AmazonSales!C:C<AmazonSales!B:B,"Check Dates", IF(AmazonSales!C:C-AmazonSales!B:B<=2,"Fast","Slow") ) ) ), ) -> Slow | C18: Cancelled | D18: South | E18: 249 | F18: PROD014
B19: =IFERROR( IF(AmazonSales!E:E<>"","Cancelled", IF(AmazonSales!C:C="","No Delivery Date", IF(AmazonSales!C:C<AmazonSales!B:B,"Check Dates", IF(AmazonSales!C:C-AmazonSales!B:B<=2,"Fast","Slow") ) ) ), ) -> No Delivery Date | C19: Delivered | D19: East | E19: 384 | F19: PROD018
B20: =IFERROR( IF(AmazonSales!E:E<>"","Cancelled", IF(AmazonSales!C:C="","No Delivery Date", IF(AmazonSales!C:C<AmazonSales!B:B,"Check Dates", IF(AmazonSales!C:C-AmazonSales!B:B<=2,"Fast","Slow") ) ) ), ) -> No Delivery Date | C20: Cancelled | D20: Central | E20: 315 | F20: PROD020
... B101: =IFERROR( IF(AmazonSales!E:E<>"","Cancelled", IF(AmazonSales!C:C="","No Delivery Date", IF(AmazonSales!C:C<AmazonSales!B:B,"Check Dates", IF(AmazonSales!C:C-AmazonSales!B:B<=2,"Fast","Slow") ) ) ), ) -> No Delivery Date | C101: In Transit | D101: West | E101: 168 | F101: PROD002

Sheet Pivot Table
A1: Show Total Sales Amount by Region and Product Category | N1: Count of Orders by Delivery Status | Y1: Average Delivery Time = Delivery Date – Order Date | AD1: Add filter for Payment Method and Product Category
A3: Region | B3: Category | C3: Total Amount | E3: Sum of Total Amount | F3: Column Labels | M3: Category | N3: Delivery Status | O3: Total Amount | Q3: Count of Order by Delivery Status | R3: Column Labels | Y3: Average Delivery Time | AC3: Category | AD3: Payment Method | AE3: Total Amount | AG3: Sum of Total Amount | AH3: Column Labels
A4: North | B4: Home | C4: 44 | E4: Row Labels | F4: Books | G4: Electronics | H4: Fashion | I4: Home | J4: Toys | K4: Grand Total | M4: Home | N4: Cancelled | O4: 44 | Q4: Row Labels | R4: Books | S4: Electronics | T4: Fashion | U4: Home | V4: Toys | W4: Grand Total | Y4: =IF(AmazonSales!C2-AmazonSales!B2<0,"",AmazonSales!C2-AmazonSales!B2) | AC4: Home | AD4: Apple Pay | AE4: 44 | AG4: Row Labels | AH4: Amazon Pay | AI4: Apple Pay | AJ4: Credit Card | AK4: Debit Card | AL4: PayPal | AM4: Grand Total
A5: East | B5: Toys | C5: 384 | E5: Central | F5: 84 | G5: 2662 | H5: 210 | I5: 2063 | J5: 437 | K5: 5456 | M5: Toys | N5: Delivered | O5: 384 | Q5: Cancelled | R5: 317 | S5: 2174 | T5: 1447 | U5: 2501 | V5: 522 | W5: 6961 | Y5: =IF(AmazonSales!C3-AmazonSales!B3<0,"",AmazonSales!C3-AmazonSales!B3) -> 2 | AA5: Average of Average Delivery Time | AC5: Toys | AD5: Credit Card | AE5: 384 | AG5: Books | AH5: 548 | AJ5: 118 | AK5: 408 | AL5: 641 | AM5: 1715
A6: South | B6: Home | C6: 776 | E6: East | F6: 394 | G6: 365 | H6: 711 | I6: 741 | J6: 1424 | K6: 3635 | M6: Home | N6: In Transit | O6: 776 | Q6: Delivered | R6: 127 | S6: 6126 | T6: 1376 | U6: 4203 | V6: 1824 | W6: 13656 | Y6: =IF(AmazonSales!C4-AmazonSales!B4<0,"",AmazonSales!C4-AmazonSales!B4) | AA6: 3.7647059 | AC6: Home | AD6: Credit Card | AE6: 776 | AG6: Electronics | AH6: 990 | AI6: 3398 | AJ6: 5490 | AK6: 3467 | AL6: 1864 | AM6: 15209
A7: North | B7: Home | C7: 588 | E7: North | F7: 464 | G7: 6522 | H7: 788 | I7: 2131 | J7: 586 | K7: 10491 | M7: Home | N7: Cancelled | O7: 588 | Q7: In Transit | R7: 1271 | S7: 6909 | T7: 1049 | U7: 4247 | V7: 1165 | W7: 14641 | Y7: =IF(AmazonSales!C5-AmazonSales!B5<0,"",AmazonSales!C5-AmazonSales!B5) | AC7: Home | AD7: PayPal | AE7: 588 | AG7: Fashion | AH7: 1064 | AI7: 686 | AJ7: 884 | AK7: 751 | AL7: 487 | AM7: 3872
A8: North | B8: Fashion | C8: 59 | E8: South | F8: 423 | G8: 3938 | H8: 1032 | I8: 1881 | J8: 43 | K8: 7317 | M8: Fashion | N8: Delivered | O8: 59 | Q8: Grand Total | R8: 1715 | S8: 15209 | T8: 3872 | U8: 10951 | V8: 3511 | W8: 35258 | Y8: =IF(AmazonSales!C6-AmazonSales!B6<0,"",AmazonSales!C6-AmazonSales!B6) -> 3 | AC8: Fashion | AD8: PayPal | AE8: 59 | AG8: Home | AH8: 1367 | AI8: 1661 | AJ8: 1439 | AK8: 2827 | AL8: 3657 | AM8: 10951
A9: North | B9: Fashion | C9: 232 | E9: West | F9: 350 | G9: 1722 | H9: 1131 | I9: 4135 | J9: 1021 | K9: 8359 | M9: Fashion | N9: Cancelled | O9: 232 | Y9: =IF(AmazonSales!C7-AmazonSales!B7<0,"",AmazonSales!C7-AmazonSales!B7) | AC9: Fashion | AD9: Amazon Pay | AE9: 232 | AG9: Toys | AH9: 750 | AI9: 399 | AJ9: 1467 | AK9: 895 | AM9: 3511
A10: Central | B10: Electronics | C10: 315 | E10: Grand Total | F10: 1715 | G10: 15209 | H10: 3872 | I10: 10951 | J10: 3511 | K10: 35258 | M10: Electronics | N10: Cancelled | O10: 315 | Y10: =IF(AmazonSales!C8-AmazonSales!B8<0,"",AmazonSales!C8-AmazonSales!B8) | AC10: Electronics | AD10: Debit Card | AE10: 315 | AG10: Grand Total | AH10: 4719 | AI10: 6144 | AJ10: 9398 | AK10: 8348 | AL10: 6649 | AM10: 35258
A11: West | B11: Home | C11: 185 | M11: Home | N11: Cancelled | O11: 185 | Y11: =IF(AmazonSales!C9-AmazonSales!B9<0,"",AmazonSales!C9-AmazonSales!B9) | AC11: Home | AD11: PayPal | AE11: 185
A12: Central | B12: Fashion | C12: 88 | M12: Fashion | N12: In Transit | O12: 88 | Y12: =IF(AmazonSales!C10-AmazonSales!B10<0,"",AmazonSales!C10-AmazonSales!B10) | AC12: Fashion | AD12: Credit Card | AE12: 88
A13: South | B13: Home | C13: 564 | M13: Home | N13: In Transit | O13: 564 | Y13: =IF(AmazonSales!C11-AmazonSales!B11<0,"",AmazonSales!C11-AmazonSales!B11) | AC13: Home | AD13: Debit Card | AE13: 564
A14: South | B14: Electronics | C14: 249 | M14: Electronics | N14: Cancelled | O14: 249 | Y14: =IF(AmazonSales!C12-AmazonSales!B12<0,"",AmazonSales!C12-AmazonSales!B12) | AC14: Electronics | AD14: Amazon Pay | AE14: 249
A15: Central | B15: Electronics | C15: 741 | M15: Electronics | N15: In Transit | O15: 741 | Y15: =IF(AmazonSales!C13-AmazonSales!B13<0,"",AmazonSales!C13-AmazonSales!B13) | AC15: Electronics | AD15: Amazon Pay | AE15: 741
A16: Central | B16: Fashion | C16: 96 | M16: Fashion | N16: Cancelled | O16: 96 | Y16: =IF(AmazonSales!C14-AmazonSales!B14<0,"",AmazonSales!C14-AmazonSales!B14) | AC16: Fashion | AD16: Apple Pay | AE16: 96
A17: West | B17: Electronics | C17: 370 | M17: Electronics | N17: Cancelled | O17: 370 | Y17: =IF(AmazonSales!C15-AmazonSales!B15<0,"",AmazonSales!C15-AmazonSales!B15) | AC17: Electronics | AD17: Apple Pay | AE17: 370
A18: South | B18: Fashion | C18: 27 | M18: Fashion | N18: Cancelled | O18: 27 | Y18: =IF(AmazonSales!C16-AmazonSales!B16<0,"",AmazonSales!C16-AmazonSales!B16) | AC18: Fashion | AD18: Credit Card | AE18: 27
A19: South | B19: Fashion | C19: 81 | M19: Fashion | N19: In Transit | O19: 81 | Y19: =IF(AmazonSales!C17-AmazonSales!B17<0,"",AmazonSales!C17-AmazonSales!B17) | AC19: Fashion | AD19: Debit Card | AE19: 81
A20: East | B20: Books | C20: 63 | M20: Books | N20: Delivered | O20: 63 | Y20: =IF(AmazonSales!C18-AmazonSales!B18<0,"",AmazonSales!C18-AmazonSales!B18) -> 3 | AC20: Books | AD20: Credit Card | AE20: 63
A21: West | B21: Books | C21: 350 | M21: Books | N21: In Transit | O21: 350 | Y21: =IF(AmazonSales!C19-AmazonSales!B19<0,"",AmazonSales!C19-AmazonSales!B19) | AC21: Books | AD21: PayPal | AE21: 350
A22: South | B22: Fashion | C22: 376 | M22: Fashion | N22: In Transit | O22: 376 | Y22: =IF(AmazonSales!C20-AmazonSales!B20<0,"",AmazonSales!C20-AmazonSales!B20) | AC22: Fashion | AD22: Credit Card | AE22: 376
... A103: West | B103: Toys | C103: 168 | M103: Toys | N103: In Transit | O103: 168 | Y103: =IF(AmazonSales!C101-AmazonSales!B101<0,"",AmazonSales!C101-AmazonSales!B101) | AC103: Toys | AD103: Debit Card | AE103: 168
B104: #N/A
B105: #N/A
B106: #N/A
B107: #N/A
B108: #N/A
B109: #N/A
B110: #N/A
B111: #N/A
B112: #N/A
B113: #N/A
B114: #N/A
B115: #N/A
... B1002: #N/A

Sheet Dashboard data
A1: Order ID | B1: Order Date | C1: Delivery Date | D1: Average Delivery Time | E1: Cancel Date | F1: Customer ID | G1: Product ID | H1: Category | I1: Region | J1: Sale Price/Unit | K1: Quantity | L1: Total Amount | M1: Payment Method | N1: Delivery Status | O1: Fulfillment Partner | R1: Column Labels | Z1: Sum of Total Amount | AA1: Column Labels | AI1: Sum of Total Amount | AJ1: Column Labels | AQ1: Row Labels | AR1: Sum of Total Amount | AT1: Row Labels | AU1: Sum of Total Amount
A2: ORD0001 | B2: 45291 | E2: 45293 | F2: CUST021 | G2: PROD012 | H2: =VLOOKUP(G2,ProductMaster!A:C,3,0) -> Home | I2: North | J2: 44 | K2: 1 | L2: 44 | M2: Apple Pay | N2: Cancelled | O2: DHL | Q2: Row Labels | R2: Books | S2: Electronics | T2: Fashion | U2: Home | V2: Toys | W2: Grand Total | Z2: Row Labels | AA2: Books | AB2: Electronics | AC2: Fashion | AD2: Home | AE2: Toys | AF2: Grand Total | AI2: Row Labels | AJ2: Amazon Pay | AK2: Apple Pay | AL2: Credit Card | AM2: Debit Card | AN2: PayPal | AO2: Grand Total | AQ2: Jan | AR2: 1099 | AT2: PROD001 | AU2: 9644
A3: ORD0002 | B3: 44979 | C3: 44981 | D3: 2 | F3: CUST029 | G3: PROD018 | H3: =VLOOKUP(G3,ProductMaster!A:C,3,0) -> Toys | I3: East | J3: 96 | K3: 4 | L3: 384 | M3: Credit Card | N3: Delivered | O3: DHL | Q3: Central | R3: 84 | S3: 2662 | T3: 210 | U3: 2063 | V3: 437 | W3: 5456 | Z3: Cancelled | AA3: 317 | AB3: 2174 | AC3: 1447 | AD3: 2501 | AE3: 522 | AF3: 6961 | AI3: Books | AJ3: 548 | AL3: 118 | AM3: 408 | AN3: 641 | AO3: 1715 | AQ3: Feb | AR3: 3712 | AT3: PROD003 | AU3: 2496
A4: ORD0003 | B4: 45210 | F4: CUST021 | G4: PROD013 | H4: =VLOOKUP(G4,ProductMaster!A:C,3,0) -> Home | I4: South | J4: 194 | K4: 4 | L4: 776 | M4: Credit Card | N4: In Transit | O4: USPS | Q4: East | R4: 394 | S4: 365 | T4: 711 | U4: 741 | V4: 1424 | W4: 3635 | Z4: Delivered | AA4: 127 | AB4: 6126 | AC4: 1376 | AD4: 4203 | AE4: 1824 | AF4: 13656 | AI4: Electronics | AJ4: 990 | AK4: 3398 | AL4: 5490 | AM4: 3467 | AN4: 1864 | AO4: 15209 | AQ4: Mar | AR4: 905 | AT4: PROD006 | AU4: 1239
A5: ORD0004 | B5: 45051 | E5: 45057 | F5: CUST044 | G5: PROD013 | H5: =VLOOKUP(G5,ProductMaster!A:C,3,0) -> Home | I5: North | J5: 196 | K5: 3 | L5: 588 | M5: PayPal | N5: Cancelled | O5: UPS | Q5: North | R5: 464 | S5: 6522 | T5: 788 | U5: 2131 | V5: 586 | W5: 10491 | Z5: In Transit | AA5: 1271 | AB5: 6909 | AC5: 1049 | AD5: 4247 | AE5: 1165 | AF5: 14641 | AI5: Fashion | AJ5: 1064 | AK5: 686 | AL5: 884 | AM5: 751 | AN5: 487 | AO5: 3872 | AQ5: Apr | AR5: 2637 | AT5: PROD008 | AU5: 1318
A6: ORD0005 | B6: 44959 | C6: 44962 | D6: 3 | F6: CUST027 | G6: PROD010 | H6: =VLOOKUP(G6,ProductMaster!A:C,3,0) -> Fashion | I6: North | J6: 59 | K6: 1 | L6: 59 | M6: PayPal | N6: Delivered | O6: Amazon Logistics | Q6: South | R6: 423 | S6: 3938 | T6: 1032 | U6: 1881 | V6: 43 | W6: 7317 | Z6: Grand Total | AA6: 1715 | AB6: 15209 | AC6: 3872 | AD6: 10951 | AE6: 3511 | AF6: 35258 | AI6: Home | AJ6: 1367 | AK6: 1661 | AL6: 1439 | AM6: 2827 | AN6: 3657 | AO6: 10951 | AQ6: May | AR6: 4940 | AT6: PROD011 | AU6: 1212
A7: ORD0006 | B7: 45231 | E7: 45232 | F7: CUST009 | G7: PROD010 | H7: =VLOOKUP(G7,ProductMaster!A:C,3,0) -> Fashion | I7: North | J7: 58 | K7: 4 | L7: 232 | M7: Amazon Pay | N7: Cancelled | O7: DHL | Q7: West | R7: 350 | S7: 1722 | T7: 1131 | U7: 4135 | V7: 1021 | W7: 8359 | AI7: Toys | AJ7: 750 | AK7: 399 | AL7: 1467 | AM7: 895 | AO7: 3511 | AQ7: Jun | AR7: 2599 | AT7: PROD013 | AU7: 2144
A8: ORD0007 | B8: 45152 | E8: 45156 | F8: CUST042 | G8: PROD020 | H8: =VLOOKUP(G8,ProductMaster!A:C,3,0) -> Electronics | I8: Central | J8: 105 | K8: 3 | L8: 315 | M8: Debit Card | N8: Cancelled | O8: DHL | Q8: Grand Total | R8: 1715 | S8: 15209 | T8: 3872 | U8: 10951 | V8: 3511 | W8: 35258 | AI8: Grand Total | AJ8: 4719 | AK8: 6144 | AL8: 9398 | AM8: 8348 | AN8: 6649 | AO8: 35258 | AQ8: Jul | AR8: 3315 | AT8: PROD014 | AU8: 2230
A9: ORD0008 | B9: 45017 | E9: 45022 | F9: CUST019 | G9: PROD021 | H9: =VLOOKUP(G9,ProductMaster!A:C,3,0) -> Home | I9: West | J9: 37 | K9: 5 | L9: 185 | M9: PayPal | N9: Cancelled | O9: DHL | AQ9: Aug | AR9: 782 | AT9: PROD016 | AU9: 5151
A10: ORD0009 | B10: 45128 | F10: CUST013 | G10: PROD019 | H10: =VLOOKUP(G10,ProductMaster!A:C,3,0) -> Fashion | I10: Central | J10: 44 | K10: 2 | L10: 88 | M10: Credit Card | N10: In Transit | O10: Amazon Logistics | AQ10: Sep | AR10: 1570 | AT10: PROD017 | AU10: 1392
A11: ORD0010 | B11: 45289 | F11: CUST019 | G11: PROD003 | H11: =VLOOKUP(G11,ProductMaster!A:C,3,0) -> Home | I11: South | J11: 141 | K11: 4 | L11: 564 | M11: Debit Card | N11: In Transit | O11: DHL | Q11: Sales | AQ11: Oct | AR11: 2920 | AT11: PROD018 | AU11: 1530
A12: ORD0011 | B12: 45050 | E12: 45054 | F12: CUST046 | G12: PROD014 | H12: =VLOOKUP(G12,ProductMaster!A:C,3,0) -> Electronics | I12: South | J12: 249 | K12: 1 | L12: 249 | M12: Amazon Pay | N12: Cancelled | O12: USPS | Q12: =SUM(W3:W7) -> 35258 | AQ12: Nov | AR12: 6312 | AT12: Grand Total | AU12: 28356
A13: ORD0012 | B13: 45132 | F13: CUST045 | G13: PROD014 | H13: =VLOOKUP(G13,ProductMaster!A:C,3,0) -> Electronics | I13: Central | J13: 247 | K13: 3 | L13: 741 | M13: Amazon Pay | N13: In Transit | O13: FedEx | Q13: Active / Successful Orders | AQ13: Dec | AR13: 4467
A14: ORD0013 | B14: 44982 | E14: 44985 | F14: CUST023 | G14: PROD006 | H14: =VLOOKUP(G14,ProductMaster!A:C,3,0) -> Fashion | I14: Central | J14: 96 | K14: 1 | L14: 96 | M14: Apple Pay | N14: Cancelled | O14: Amazon Logistics | Q14: =GETPIVOTDATA("Total Amount",$Z$1,"Delivery Status","Delivered")+GETPIVOTDATA("Total Amount",$Z$1,"Delivery Status","In Transit") -> 28297 | AQ14: Grand Total | AR14: 35258
A15: ORD0014 | B15: 44981 | E15: 44982 | F15: CUST033 | G15: PROD017 | H15: =VLOOKUP(G15,ProductMaster!A:C,3,0) -> Electronics | I15: West | J15: 74 | K15: 5 | L15: 370 | M15: Apple Pay | N15: Cancelled | O15: Amazon Logistics
A16: ORD0015 | B16: 45164 | E16: 45171 | F16: CUST033 | G16: PROD005 | H16: =VLOOKUP(G16,ProductMaster!A:C,3,0) -> Fashion | I16: South | J16: 27 | K16: 1 | L16: 27 | M16: Credit Card | N16: Cancelled | O16: Amazon Logistics | Q16: Highest Selling product
A17: ORD0016 | B17: 44970 | F17: CUST047 | G17: PROD005 | H17: =VLOOKUP(G17,ProductMaster!A:C,3,0) -> Fashion | I17: South | J17: 27 | K17: 3 | L17: 81 | M17: Debit Card | N17: In Transit | O17: Amazon Logistics | Q17: =INDEX(AT2:AT11, MATCH(MAX(AU2:AU11), AU2:AU11, 0)) -> PROD001
A18: ORD0017 | B18: 45105 | C18: 45108 | D18: 3 | F18: CUST045 | G18: PROD015 | H18: =VLOOKUP(G18,ProductMaster!A:C,3,0) -> Books | I18: East | J18: 21 | K18: 3 | L18: 63 | M18: Credit Card | N18: Delivered | O18: DHL
A19: ORD0018 | B19: 45258 | F19: CUST011 | G19: PROD008 | H19: =VLOOKUP(G19,ProductMaster!A:C,3,0) -> Books | I19: West | J19: 70 | K19: 5 | L19: 350 | M19: PayPal | N19: In Transit | O19: Amazon Logistics | Q19: Cancel Product Value
A20: ORD0019 | B20: 45163 | F20: CUST041 | G20: PROD006 | H20: =VLOOKUP(G20,ProductMaster!A:C,3,0) -> Fashion | I20: South | J20: 94 | K20: 4 | L20: 376 | M20: Credit Card | N20: In Transit | O20: USPS | Q20: =GETPIVOTDATA("Total Amount",$Z$1,"Delivery Status","Cancelled") -> 6961
A21: ORD0020 | B21: 45028 | F21: CUST025 | G21: PROD001 | H21: =VLOOKUP(G21,ProductMaster!A:C,3,0) -> Electronics | I21: North | J21: 813 | K21: 2 | L21: 1626 | M21: Credit Card | N21: In Transit | O21: FedEx
A22: ORD0021 | B22: 45201 | F22: CUST013 | G22: PROD015 | H22: =VLOOKUP(G22,ProductMaster!A:C,3,0) -> Books | I22: Central | J22: 21 | K22: 4 | L22: 84 | M22: PayPal | N22: In Transit | O22: Amazon Logistics
A23: ORD0022 | B23: 45239 | F23: CUST023 | G23: PROD012 | H23: =VLOOKUP(G23,ProductMaster!A:C,3,0) -> Home | I23: West | J23: 46 | K23: 5 | L23: 230 | M23: PayPal | N23: In Transit | O23: USPS
A24: ORD0023 | B24: 44970 | E24: 44971 | F24: CUST016 | G24: PROD010 | H24: =VLOOKUP(G24,ProductMaster!A:C,3,0) -> Fashion | I24: West | J24: 58 | K24: 3 | L24: 174 | M24: Amazon Pay | N24: Cancelled | O24: Amazon Logistics
A25: ORD0024 | B25: 45232 | C25: 45235 | D25: 3 | F25: CUST028 | G25: PROD006 | H25: =VLOOKUP(G25,ProductMaster!A:C,3,0) -> Fashion | I25: West | J25: 96 | K25: 5 | L25: 480 | M25: Amazon Pay | N25: Delivered | O25: Amazon Logistics
A26: ORD0025 | B26: 45074 | C26: 45076 | D26: 2 | F26: CUST040 | G26: PROD002 | H26: =VLOOKUP(G26,ProductMaster!A:C,3,0) -> Toys | I26: South | J26: 43 | K26: 1 | L26: 43 | M26: Debit Card | N26: Delivered | O26: Amazon Logistics
A27: ORD0026 | B27: 45214 | C27: 45220 | D27: 6 | F27: CUST027 | G27: PROD022 | H27: =VLOOKUP(G27,ProductMaster!A:C,3,0) -> Fashion | I27: South | J27: 64 | K27: 4 | L27: 256 | M27: Debit Card | N27: Delivered | O27: USPS
A28: ORD0027 | B28: 44942 | F28: CUST018 | G28: PROD008 | H28: =VLOOKUP(G28,ProductMaster!A:C,3,0) -> Books | I28: South | J28: 70 | K28: 2 | L28: 140 | M28: Amazon Pay | N28: In Transit | O28: Amazon Logistics
A29: ORD0028 | B29: 45208 | F29: CUST018 | G29: PROD018 | H29: =VLOOKUP(G29,ProductMaster!A:C,3,0) -> Toys | I29: Central | J29: 97 | K29: 3 | L29: 291 | M29: Credit Card | N29: In Transit | O29: Amazon Logistics
A30: ORD0029 | B30: 45206 | E30: 45209 | F30: CUST007 | G30: PROD021 | H30: =VLOOKUP(G30,ProductMaster!A:C,3,0) -> Home | I30: East | J30: 37 | K30: 3 | L30: 111 | M30: Apple Pay | N30: Cancelled | O30: DHL
A31: ORD0030 | B31: 44971 | F31: CUST008 | G31: PROD008 | H31: =VLOOKUP(G31,ProductMaster!A:C,3,0) -> Books | I31: North | J31: 69 | K31: 5 | L31: 345 | M31: Amazon Pay | N31: In Transit | O31: Amazon Logistics
A32: ORD0031 | B32: 45011 | F32: CUST014 | G32: PROD002 | H32: =VLOOKUP(G32,ProductMaster!A:C,3,0) -> Toys | I32: North | J32: 42 | K32: 5 | L32: 210 | M32: Amazon Pay | N32: In Transit | O32: UPS
A33: ORD0032 | B33: 45092 | E33: 45099 | F33: CUST037 | G33: PROD009 | H33: =VLOOKUP(G33,ProductMaster!A:C,3,0) -> Books | I33: East | J33: 11 | K33: 5 | L33: 55 | M33: Debit Card | N33: Cancelled | O33: FedEx
A34: ORD0033 | B34: 45068 | C34: 45069 | D34: 1 | F34: CUST016 | G34: PROD005 | H34: =VLOOKUP(G34,ProductMaster!A:C,3,0) -> Fashion | I34: South | J34: 27 | K34: 2 | L34: 54 | M34: Apple Pay | N34: Delivered | O34: USPS
A35: ORD0034 | B35: 45250 | F35: CUST025 | G35: PROD015 | H35: =VLOOKUP(G35,ProductMaster!A:C,3,0) -> Books | I35: South | J35: 21 | K35: 1 | L35: 21 | M35: Amazon Pay | N35: In Transit | O35: DHL
A36: ORD0035 | B36: 45282 | C36: 45286 | D36: 4 | F36: CUST032 | G36: PROD011 | H36: =VLOOKUP(G36,ProductMaster!A:C,3,0) -> Electronics | I36: South | J36: 172 | K36: 1 | L36: 172 | M36: PayPal | N36: Delivered | O36: USPS
A37: ORD0036 | B37: 45130 | F37: CUST014 | G37: PROD016 | H37: =VLOOKUP(G37,ProductMaster!A:C,3,0) -> Home | I37: North | J37: 212 | K37: 3 | L37: 636 | M37: Amazon Pay | N37: In Transit | O37: UPS
A38: ORD0037 | B38: 45216 | C38: 45221 | D38: 5 | F38: CUST044 | G38: PROD002 | H38: =VLOOKUP(G38,ProductMaster!A:C,3,0) -> Toys | I38: East | J38: 41 | K38: 4 | L38: 164 | M38: Credit Card | N38: Delivered | O38: Amazon Logistics
A39: ORD0038 | B39: 45160 | E39: 45162 | F39: CUST028 | G39: PROD007 | H39: =VLOOKUP(G39,ProductMaster!A:C,3,0) -> Toys | I39: North | J39: 32 | K39: 2 | L39: 64 | M39: Debit Card | N39: Cancelled | O39: FedEx
A40: ORD0039 | B40: 45262 | F40: CUST024 | G40: PROD022 | H40: =VLOOKUP(G40,ProductMaster!A:C,3,0) -> Fashion | I40: East | J40: 66 | K40: 2 | L40: 132 | M40: Apple Pay | N40: In Transit | O40: DHL
...

Sheet Dashboard

Sheet ProductMaster
A1: Product ID | B1: Product Name | C1: Category | D1: Cost Price | E1: Description
A2: PROD001 | B2: Smartphone | C2: Electronics | D2: 749 | E2: Latest model with 5G, dual SIM, and OLED display
A3: PROD002 | B3: Action Figure | C3: Toys | D3: 39 | E3: Collectible superhero action figure for ages 8+
A4: PROD003 | B4: Cookware Set | C4: Home | D4: 129 | E4: Non-stick 5-piece cookware set for daily use
A5: PROD004 | B5: Leg Set | C5: Toys | D5: 59 | E5: 300-piece creative building block toy set
A6: PROD005 | B6: T-Shirt | C6: Fashion | D6: 25 | E6: Cotton t-shirt, available in multiple colors
A7: PROD006 | B7: Shoes | C7: Fashion | D7: 89 | E7: Casual wear shoes for men and women
A8: PROD007 | B8: Puzzle | C8: Toys | D8: 29 | E8: 1000-piece jigsaw puzzle
A9: PROD008 | B9: Textbook | C9: Books | D9: 65 | E9: University-level textbook on computer science
A10: PROD009 | B10: Magazine | C10: Books | D10: 10 | E10: Monthly lifestyle magazine
A11: PROD010 | B11: Jeans | C11: Fashion | D11: 55 | E11: Slim fit denim jeans with stretch
A12: PROD011 | B12: Headphones | C12: Electronics | D12: 159 | E12: Wireless noise-cancelling over-ear headphones
A13: PROD012 | B13: Lamp | C13: Home | D13: 42 | E13: LED desk lamp with dimmable light
... A23: PROD022 | B23: Backpack | C23: Fashion | D23: 60 | E23: Waterproof backpack with laptop compartment

Sheet RegionGoals
A1: Region | B1: Sales Target
A2: Central | B2: 97500
A3: East | B3: 50500
A4: North | B4: 105000
A5: South | B5: 91500
A6: West | B6: 90750

Sheet CustomerMaster
A1: Customer ID | B1: Customer Name | C1: Customer Type | D1: City | E1: State
A2: CUST001 | B2: James Miller | C2: Business | D2: New York | E2: New York
A3: CUST002 | B3: Emily Johnson | C3: Prime | D3: Seattle | E3: Washington
A4: CUST003 | B4: Ethan Davis | C4: Prime | D4: Austin | E4: Texas
A5: CUST004 | B5: Noah Wilson | C5: Prime | D5: San Francisco | E5: California
A6: CUST005 | B6: Olivia Martinez | C6: Prime | D6: Seattle | E6: Washington
A7: CUST006 | B7: Ava Robinson | C7: Prime | D7: Chicago | E7: Illinois
A8: CUST007 | B8: Liam Walker | C8: Prime | D8: San Francisco | E8: California
A9: CUST008 | B9: Harper Young | C9: Business | D9: Dallas | E9: Texas
A10: CUST009 | B10: Jackson Allen | C10: Business | D10: Seattle | E10: Washington
A11: CUST010 | B11: Charlotte Harris | C11: Prime | D11: Chicago | E11: Illinois
A12: CUST011 | B12: Mason Hall | C12: Business | D12: Miami | E12: Florida
... A50: CUST049 | B50: Hazel Gray | C50: Business | D50: Chicago | E50: Illinois
